Workbook

Sheet Hoja1
A1: Ref | B1: Nombre | C1: Peso (g) | D1: Material
B2: Peso Total | C2: =SUM(C6:C7,C9:C14,C17:C21,C23:C38,C40:C42,C44,C46:C47,C49:C58,C60:C63,C65:C67) -> 2299 | D2: 2400 g Teórico
A3: 1 | B3: Cuerpo
A4: 1.1 | B4: Estructura Cuerpo
A5: 1.1.1 | B5: Carcasa Cuerpo Exterior
A6: 1.1.1.1 | B6: Carcasa Cuerpo Exterior Izquierdo | C6: 113 | D6: ABS | E6: Acrilonitrilo butadieno estireno | F6: https://es.wikipedia.org/wiki/Acrilonitrilo_butadieno_estireno | G6: Polímeros
A7: 1.1.1.2 | B7: Carcasa Cuerpo Exterior Derecho | C7: 115 | D7: ABS | E7: Acrilonitrilo butadieno estireno | F7: https://es.wikipedia.org/wiki/Acrilonitrilo_butadieno_estireno | G7: Polímeros
A8: 1.1.2 | B8: Carcasa Cuerpo Interior
A9: 1.1.2.1 | B9: Carcasa Cuerpo Interior Izquierdo | C9: 161 | D9: ABS | E9: Acrilonitrilo butadieno estireno | F9: https://es.wikipedia.org/wiki/Acrilonitrilo_butadieno_estireno | G9: Polímeros
A10: 1.1.2.2 | B10: Carcasa Cuerpo Interior Derecho | C10: 246 | D10: ABS | E10: Acrilonitrilo butadieno estireno | F10: https://es.wikipedia.org/wiki/Acrilonitrilo_butadieno_estireno | G10: Polímeros
A11: 1.1.3 | B11: Manivela | C11: 145 | E11: *Metal* | G11: Metálico
A12: 1.1.4.1 | B12: Unión Manivela Izquierda | C12: 9 | D12: PPA | E12: Poliftalamida (PA6T/6I) | F12: https://en.wikipedia.org/wiki/Polyphthalamide | G12: Polímeros
A13: 1.1.4.2 | B13: Unión Manivela Derecha | C13: 9 | D13: PPA | E13: Poliftalamida (PA6T/6I) | F13: https://en.wikipedia.org/wiki/Polyphthalamide | G13: Polímeros
A14: 1.1.5 | B14: Botonera | C14: 7 | D14: Caucho | E14: *Goma* (T4-21) | G14: Polímeros
A15: 1.2 | B15: Bomba Vibratoria Ulka
A16: 1.2.1 | B16: Tuberia
A17: 1.2.1.1 | B17: Tuberia Tanque Turbina | C17: 6 | D17: Caucho | E17: *Goma* (T2/8) | G17: Polímeros
A18: 1.2.1.2 | B18: Turbina | C18: 4 | D18: PP | E18: Polipropileno | G18: Polímeros
A19: 1.2.1.3 | B19: Tuberia Turbina Bomba | C19: 5 | D19: Caucho | E19: *Goma*(ST1/1) | G19: Polímeros
A20: 1.2.1.4 | B20: Soporte | C20: 3 | D20: NBR | E20: Caucho nitrílico | F20: https://en.wikipedia.org/wiki/Nitrile_rubber | G20: Polímeros
A21: 1.2.1.5 | B21: Muelle | C21: 2 | E21: *metal* | G21: Metálico
A22: 1.2.2 | B22: Bomba | D22: 370 | F22: =SUM(C23:C38) -> 368
A23: 1.2.2.1 | B23: Soporte Bomba | C23: 119 | E23: *metal* | G23: Metálico
A24: 1.2.2.2 | B24: Bobina | C24: 155 | D24: ABS | E24: Acrilonitrilo butadieno estireno* | G24: Polímeros
A25: 1.2.2.3 | B25: Anillo Intermedio | C25: 1 | D25: LDPE | E25: Polietileno de baja densidad | G25: Polímeros
A26: 1.2.2.4 | B26: Anillo Exterior 1 | C26: 19 | E26: *metal* | G26: Metálico
A27: 1.2.2.5 | B27: Anillo Exterior 2 | C27: 19 | E27: *metal* | G27: Metálico
A28: 1.2.2.6 | B28: Junta Aislante | C28: 0 | D28: Caucho | E28: *Goma* | G28: Polímeros
A29: 1.2.2.7 | B29: Tubo Entrada | C29: 6 | D29: LDPE | E29: Polietileno de baja densidad | G29: Polímeros
A30: 1.2.2.8 | B30: Tubo Salida | C30: 10 | D30: LDPE | E30: Polietileno de baja densidad | G30: Polímeros
A31: 1.2.2.9 | B31: Piston de Entrada | C31: 9 | E31: *metal* | G31: Metálico
A32: 1.2.2.10 | B32: Piston de Salida | C32: 21 | E32: *metal* | G32: Metálico
A33: 1.2.2.11 | B33: Muelle Entrada | C33: 2 | E33: *metal* | G33: Metálico
A34: 1.2.2.12 | B34: Muelle Salida | C34: 4 | E34: *metal* | G34: Metálico
A35: 1.2.2.13 | B35: Arandela | C35: 1 | D35: LDPE | E35: Polietileno de baja densidad | G35: Polímeros
A36: 1.2.2.14 | B36: Canal Valvula | C36: 2 | D36: ABS | E36: Acrilonitrilo butadieno estireno* | G36: Polímeros
A37: 1.2.2.15 | B37: Valvula + Muelle | C37: 0 | D37: Varios | E37: Varios | G37: Varios
A38: 1.2.2.16 | B38: Junta Aislante | C38: 0 | D38: Caucho | E38: *Goma* | G38: Polímeros
A39: 1.3 | B39: Circuiteria Central
A40: 1.3.1 | B40: Placa Base | C40: 19 | D40: Varios | E40: Varios | G40: Varios
...

Sheet Hoja2
A1: Composición de Materiales | B1: =SUM(F1,F12,F16,F20) -> 2299 | C1: =SUM(C2:C6) -> 1 | E1: Polimeros | F1: =SUMIF(Hoja1!G6:G67,"=Polímeros",Hoja1!C6:C67) -> 1290 | G1: =F1/$F$1 -> 1 | I1: Porcetaje de Peso por Elemento | J1: =SUM(J2:J7) -> 1945 | K1: =J1/$J$1 -> 1 | M1: Tanque (3) | N1: =SUM(N2:N4) -> 145 | O1: =SUM(O2:O4) -> 1
A2: Polímeros | B2: =F1 -> 1290 | C2: =B2/$B$1 -> 0.56111353 | E2: ABS | F2: =SUMIF(Hoja1!$D$6:$D$67,E2,Hoja1!$C$6:$C$67) -> 1012 | G2: =F2/$F$1 -> 0.78449612 | I2: Estructura del Cuerpo(1.1) | J2: =N11 -> 805 | K2: =J2/$J$1 -> 0.41388175 | M2: SAN | N2: =SUMIF(Hoja1!$D$65:$D$67,Hoja2!M2,Hoja1!$C$65:$C$67) -> 131 | O2: =N2/$N$1 -> 0.90344828
A3: Metálico | B3: =F12 -> 745 | C3: =B3/$B$1 -> 0.32405394 | E3: PPA | F3: =SUMIF(Hoja1!$D$6:$D$67,E3,Hoja1!$C$6:$C$67) -> 18 | G3: =F3/$F$1 -> 0.013953488 | I3: Bomba Vibratoria Ulka(1.2) | J3: =N18 -> 388 | K3: =J3/$J$1 -> 0.19948586 | M3: PP | N3: =SUMIF(Hoja1!$D$65:$D$67,Hoja2!M3,Hoja1!$C$65:$C$67) -> 13 | O3: =N3/$N$1 -> 0.089655172
A4: Compuesto | B4: =F16 -> 225 | C4: =B4/$B$1 -> 0.097868639 | E4: PP | F4: =SUMIF(Hoja1!$D$6:$D$67,E4,Hoja1!$C$6:$C$67) -> 27 | G4: =F4/$F$1 -> 0.020930233 | I4: Circuiteria(1.3) | J4: =N28 -> 40 | K4: =J4/$J$1 -> 0.020565553 | M4: Varios | N4: =SUMIF(Hoja1!$D$65:$D$67,Hoja2!M4,Hoja1!$C$65:$C$67) -> 1 | O4: =N4/$N$1 -> 0.0068965517
A5: Ceramico | B5: 0 | C5: =B5/$B$1 -> 0 | E5: NBR | F5: =SUMIF(Hoja1!$D$6:$D$67,E5,Hoja1!$C$6:$C$67) -> 3 | G5: =F5/$F$1 -> 0.0023255814 | I5: Caldera(1.4) | J5: =N34 -> 417 | K5: =J5/$J$1 -> 0.21439589
A6: Varios | B6: =F20 -> 39 | C6: =B6/$B$1 -> 0.016963897 | E6: LDPE | F6: =SUMIF(Hoja1!$D$6:$D$67,E6,Hoja1!$C$6:$C$67) -> 18 | G6: =F6/$F$1 -> 0.013953488 | I6: Porta Taza(2) | J6: =N7 -> 150 | K6: =J6/$J$1 -> 0.077120823
E7: PA | F7: =SUMIF(Hoja1!$D$6:$D$67,E7,Hoja1!$C$6:$C$67) -> 58 | G7: =F7/$F$1 -> 0.04496124 | I7: Tanque (3) | J7: =N1 -> 145 | K7: =J7/$J$1 -> 0.074550129 | M7: Porta Taza(2) | N7: =SUM(N8:N8) -> 150 | O7: =SUM(O8:O11) -> 2
E8: PA 66 | F8: =SUMIF(Hoja1!$D$6:$D$67,E8,Hoja1!$C$6:$C$67) -> 5 | G8: =F8/$F$1 -> 0.003875969 | M8: ABS | N8: =SUMIF(Hoja1!$D$60:$D$63,Hoja2!M8,Hoja1!$C$60:$C$63) -> 150 | O8: =N8/$N$7 -> 1
E9: SAN | F9: =SUMIF(Hoja1!$D$6:$D$67,E9,Hoja1!$C$6:$C$67) -> 131 | G9: =F9/$F$1 -> 0.10155039
E10: Caucho | F10: =SUMIF(Hoja1!$D$6:$D$67,E10,Hoja1!$C$6:$C$67) -> 18 | G10: =F10/$F$1 -> 0.013953488
M11: Estructura del Cuerpo(1.1) | N11: =SUM(N12:N15) -> 805 | O11: =SUM(O12:O15) -> 1
E12: Metálico | F12: =SUMIF(Hoja1!$G$6:$G$67,E12,Hoja1!$C$6:$C$67) -> 745 | G12: =F12/$F$12 -> 1 | M12: ABS | N12: =SUMIF(Hoja1!$D$6:$D$14,Hoja2!M12,Hoja1!$C$6:$C$14) -> 635 | O12: =N12/$N$11 -> 0.78881988
M13: PPA | N13: =SUMIF(Hoja1!$D$6:$D$14,Hoja2!M13,Hoja1!$C$6:$C$14) -> 18 | O13: =N13/$N$11 -> 0.022360248
M14: Caucho | N14: =SUMIF(Hoja1!$D$6:$D$14,Hoja2!M14,Hoja1!$C$6:$C$14) -> 7 | O14: =N14/$N$11 -> 0.0086956522
M15: Metal | N15: =Hoja1!C11 -> 145 | O15: =N15/$N$11 -> 0.18012422
E16: Compuesto | F16: =SUMIF(Hoja1!$G$6:$G$67,E16,Hoja1!$C$6:$C$67) -> 225 | G16: =F16/$F$16 -> 1
E17: PA 6 - GF | F17: =SUMIF(Hoja1!$D$6:$D$67,E17,Hoja1!$C$6:$C$67) -> 63 | G17: =F17/$F$16 -> 0.28
E18: PA 66 - GF | F18: =SUMIF(Hoja1!$D$6:$D$67,E18,Hoja1!$C$6:$C$67) -> 162 | G18: =F18/$F$16 -> 0.72 | M18: Bomba Vibratoria Ulka(1.2) | N18: =SUM(N19:N25) -> 388 | O18: =N18/$N$18 -> 1
M19: Caucho | N19: =SUMIF(Hoja1!$D$15:$D$38,Hoja2!M19,Hoja1!$C$15:$C$38) -> 11 | O19: =N19/$N$18 -> 0.028350515
E20: Varios | F20: =SUMIF(Hoja1!$G$6:$G$67,E20,Hoja1!$C$6:$C$67) -> 39 | M20: PP | N20: =SUMIF(Hoja1!$D$15:$D$38,Hoja2!M20,Hoja1!$C$15:$C$38) -> 4 | O20: =N20/$N$18 -> 0.010309278
M21: NBR | N21: =SUMIF(Hoja1!$D$15:$D$38,Hoja2!M21,Hoja1!$C$15:$C$38) -> 3 | O21: =N21/$N$18 -> 0.0077319588
M22: ABS | N22: =SUMIF(Hoja1!$D$15:$D$38,Hoja2!M22,Hoja1!$C$15:$C$38) -> 157 | O22: =N22/$N$18 -> 0.40463918
M23: LDPE | N23: =SUMIF(Hoja1!$D$15:$D$38,Hoja2!M23,Hoja1!$C$15:$C$38) -> 18 | O23: =N23/$N$18 -> 0.046391753
M24: Metal | N24: =SUM(Hoja1!C21,Hoja1!C23,Hoja1!C26,Hoja1!C27,Hoja1!C31:C34) -> 195 | O24: =N24/$N$18 -> 0.50257732
M25: Varios | N25: =SUMIF(Hoja1!$D$15:$D$38,Hoja2!M25,Hoja1!$C$15:$C$38) -> 0 | O25: =N25/$N$18 -> 0
M28: Circuiteria(1.3) | N28: =SUM(N29:N31) -> 40 | O28: =N28/$N$28 -> 1
M29: PA | N29: =SUMIF(Hoja1!$D$40:$D$42,Hoja2!M29,Hoja1!$C$40:$C$42) -> 16 | O29: =N29/$N$28 -> 0.4
M30: PA 66 | N30: =SUMIF(Hoja1!$D$40:$D$42,Hoja2!M30,Hoja1!$C$40:$C$42) -> 5 | O30: =N30/$N$28 -> 0.125
M31: Varios | N31: =SUMIF(Hoja1!$D$40:$D$42,Hoja2!M31,Hoja1!$C$40:$C$42) -> 19 | O31: =N31/$N$28 -> 0.475
M34: Caldera(1.4) | N34: =SUM(N35:N40) -> 417 | O34: =N34/$N$34 -> 1
M35: ABS | N35: =SUMIF(Hoja1!$D$43:$D$58,Hoja2!M35,Hoja1!$C$43:$C$58) -> 70 | O35: =N35/$N$34 -> 0.16786571
M36: PP | N36: =SUMIF(Hoja1!$D$43:$D$58,Hoja2!M36,Hoja1!$C$43:$C$58) -> 10 | O36: =N36/$N$34 -> 0.023980815
M37: PA | N37: =SUMIF(Hoja1!$D$43:$D$58,Hoja2!M37,Hoja1!$C$43:$C$58) -> 42 | O37: =N37/$N$34 -> 0.10071942
M38: ABS | N38: =SUMIF(Hoja1!$D$43:$D$58,Hoja2!M38,Hoja1!$C$43:$C$58) -> 70 | O38: =N38/$N$34 -> 0.16786571
M39: PA 6 - GF | N39: =SUMIF(Hoja1!$D$43:$D$58,Hoja2!M39,Hoja1!$C$43:$C$58) -> 63 | O39: =N39/$N$34 -> 0.15107914
M40: PA 66 - GF | N40: =SUMIF(Hoja1!$D$43:$D$58,Hoja2!M40,Hoja1!$C$43:$C$58) -> 162 | O40: =N40/$N$34 -> 0.38848921
